<?xml version="1.0" ?>
<!-- =================================================================================== -->
<!-- |    This document was autogenerated by xacro from marvin.urdf                    | -->
<!-- |    EDITING THIS FILE BY HAND IS NOT RECOMMENDED                                 | -->
<!-- =================================================================================== -->
<robot name="marvin">
  <link name="base_link">
    <inertial>
      <origin rpy="0 0 0" xyz="4.7705E-17 0.073876 5.5262E-18"/>
      <mass value="133.74"/>
      <inertia ixx="1.4976" ixy="-1.8169E-18" ixz="3.855E-09" iyy="2.3044" iyz="-1.0676E-16" izz="1.4976"/>
    </inertial>
    <visual>
      <origin rpy="0 0 0" xyz="0 0 0"/>
      <geometry>
        <mesh filename="package://marvin_description/meshes/base_link.STL"/>
      </geometry>
      <material name="">
        <color rgba="0.52941 0.54902 0.54902 1"/>
      </material>
    </visual>
    <collision>
      <origin rpy="0 0 0" xyz="0 0 0"/>
      <geometry>
        <mesh filename="package://marvin_description/meshes/base_link.STL"/>
      </geometry>
    </collision>
  </link>
  <link name="link_1">
    <inertial>
      <origin rpy="0 0 0" xyz="-2.5737E-14 0.094534 7.8988E-11"/>
      <mass value="24.106"/>
      <inertia ixx="0.20515" ixy="1.9756E-14" ixz="1.1058E-11" iyy="0.15313" iyz="-5.8138E-11" izz="0.19803"/>
    </inertial>
    <visual>
      <origin rpy="0 0 0" xyz="0 0 0"/>
      <geometry>
        <mesh filename="package://marvin_description/meshes/link_1.STL"/>
      </geometry>
      <material name="">
        <color rgba="0.83922 0.83922 0.92157 1"/>
      </material>
    </visual>
    <collision>
      <origin rpy="0 0 0" xyz="0 0 0"/>
      <geometry>
        <mesh filename="package://marvin_description/meshes/link_1.STL"/>
      </geometry>
    </collision>
  </link>
  <joint name="joint_1" type="revolute">
    <origin rpy="0 -1.5708 0" xyz="0 0.405 0"/>
    <parent link="base_link"/>
    <child link="link_1"/>
    <axis xyz="0 0 0"/>
    <limit effort="300" lower="0" upper="3.142" velocity="3"/>
  </joint>
  <link name="link_22">
    <inertial>
      <origin rpy="0 0 0" xyz="-1.0537E-16 -0.16752 1.7347E-18"/>
      <mass value="43.576"/>
      <inertia ixx="0.98533" ixy="-1.1733E-16" ixz="8.4571E-18" iyy="0.088926" iyz="9.205E-17" izz="1.0071"/>
    </inertial>
    <visual>
      <origin rpy="0 0 0" xyz="0 0 0"/>
      <geometry>
        <mesh filename="package://marvin_description/meshes/link_22.STL"/>
      </geometry>
      <material name="">
        <color rgba="1 0.6902 0.5098 1"/>
      </material>
    </visual>
    <collision>
      <origin rpy="0 0 0" xyz="0 0 0"/>
      <geometry>
        <mesh filename="package://marvin_description/meshes/link_22.STL"/>
      </geometry>
    </collision>
  </link>
  <joint name="joint_2" type="revolute">
    <origin rpy="0 0 0" xyz="0 0 0"/>
    <parent link="link_1"/>
    <child link="link_22"/>
    <axis xyz="0 0 0"/>
    <limit effort="200" lower="-1.57" upper="1.57" velocity="3"/>
  </joint>
  <link name="link_3">
    <inertial>
      <origin rpy="0 0 0" xyz="-0.17893 -0.4 -2.7235E-16"/>
      <mass value="22.044"/>
      <inertia ixx="0.057752" ixy="6.2611E-17" ixz="1.1658E-16" iyy="0.2227" iyz="-2.7094E-09" izz="0.196"/>
    </inertial>
    <visual>
      <origin rpy="0 0 0" xyz="0 0 0"/>
      <geometry>
        <mesh filename="package://marvin_description/meshes/link_3.STL"/>
      </geometry>
      <material name="">
        <color rgba="0.83922 0.83922 0.92157 1"/>
      </material>
    </visual>
    <collision>
      <origin rpy="0 0 0" xyz="0 0 0"/>
      <geometry>
        <mesh filename="package://marvin_description/meshes/link_3.STL"/>
      </geometry>
    </collision>
  </link>
  <joint name="joint_3" type="revolute">
    <origin rpy="0 0 0" xyz="0 0 0"/>
    <parent link="link_22"/>
    <child link="link_3"/>
    <axis xyz="0 0 0"/>
    <limit effort="200" lower="0" upper="3.142" velocity="3"/>
  </joint>
  <link name="link_4">
    <inertial>
      <origin rpy="0 0 0" xyz="-0.40167 0.4 -1.0842E-16"/>
      <mass value="14.116"/>
      <inertia ixx="0.018027" ixy="-3.7045E-17" ixz="-1.5488E-18" iyy="0.07496" iyz="1.6804E-19" izz="0.073248"/>
    </inertial>
    <visual>
      <origin rpy="0 0 0" xyz="0 0 0"/>
      <geometry>
        <mesh filename="package://marvin_description/meshes/link_4.STL"/>
      </geometry>
      <material name="">
        <color rgba="1 0.6902 0.5098 1"/>
      </material>
    </visual>
    <collision>
      <origin rpy="0 0 0" xyz="0 0 0"/>
      <geometry>
        <mesh filename="package://marvin_description/meshes/link_4.STL"/>
      </geometry>
    </collision>
  </link>
  <joint name="joint_4" type="revolute">
    <origin rpy="3.1416 0 -1.5708" xyz="0.05 -0.75 0"/>
    <parent link="link_3"/>
    <child link="link_4"/>
    <axis xyz="0 0 0"/>
    <limit effort="200" lower="0" upper="-3.142" velocity="3"/>
  </joint>
  <link name="link_5">
    <inertial>
      <origin rpy="0 0 0" xyz="-0.558543881206724 0.4 -3.81639164714898E-17"/>
      <mass value="1.48616706965233"/>
      <inertia ixx="0.00235532754630849" ixy="-3.3107237909334E-19" ixz="3.90379197077206E-19" iyy="0.00177970514063146" iyz="-1.53376623170845E-10" izz="0.000923748330587561"/>
    </inertial>
    <visual>
      <origin rpy="0 0 0" xyz="0 0 0"/>
      <geometry>
        <mesh filename="package://marvin_description/meshes/link_5.STL"/>
      </geometry>
      <material name="">
        <color rgba="1 0.690196078431373 0.509803921568627 1"/>
      </material>
    </visual>
    <collision>
      <origin rpy="0 0 0" xyz="0 0 0"/>
      <geometry>
        <mesh filename="package://marvin_description/meshes/link_5.STL"/>
      </geometry>
    </collision>
  </link>
  <joint name="joint_5" type="revolute">
    <origin rpy="0 0 0" xyz="0.002 0 0"/>
    <parent link="link_4"/>
    <child link="link_5"/>
    <axis xyz="0 0 0"/>
    <limit effort="200" lower="0" upper="3.142" velocity="3"/>
  </joint>
  <link name="link_6">
    <inertial>
      <origin rpy="0 0 0" xyz="-0.60237 0.4 -0.016013"/>
      <mass value="0.11653"/>
      <inertia ixx="3.9246E-05" ixy="-4.7702E-20" ixz="1.0258E-05" iyy="7.1189E-05" iyz="-4.3552E-20" izz="8.4875E-05"/>
    </inertial>
    <visual>
      <origin rpy="0 0 0" xyz="0 0 0"/>
      <geometry>
        <mesh filename="package://marvin_description/meshes/link_6.STL"/>
      </geometry>
      <material name="">
        <color rgba="0.29412 0.29412 0.29412 1"/>
      </material>
    </visual>
    <collision>
      <origin rpy="0 0 0" xyz="0 0 0"/>
      <geometry>
        <mesh filename="package://marvin_description/meshes/link_6.STL"/>
      </geometry>
    </collision>
  </link>
  <joint name="joint_6" type="prismatic">
    <origin rpy="0 0 0" xyz="0 0 0"/>
    <parent link="link_5"/>
    <child link="link_6"/>
    <axis xyz="0 0 0"/>
    <limit effort="100" lower="0" upper="0.03" velocity="3"/>
  </joint>
  <link name="link_7">
    <inertial>
      <origin rpy="0 0 0" xyz="-0.602368573581709 0.4 -0.0160129768886558"/>
      <mass value="0.116532917792388"/>
      <inertia ixx="3.92458903876179E-05" ixy="5.94160147879759E-20" ixz="1.0257925743157E-05" iyy="7.11886398907221E-05" iyz="-7.79532126330771E-20" izz="8.48753968585245E-05"/>
    </inertial>
    <visual>
      <origin rpy="0 0 0" xyz="0 0 0"/>
      <geometry>
        <mesh filename="package://marvin_description/meshes/link_7.STL"/>
      </geometry>
      <material name="">
        <color rgba="0.294117647058824 0.294117647058824 0.294117647058824 1"/>
      </material>
    </visual>
    <collision>
      <origin rpy="0 0 0" xyz="0 0 0"/>
      <geometry>
        <mesh filename="package://marvin_description/meshes/link_7.STL"/>
      </geometry>
    </collision>
  </link>
  <joint name="joint_7" type="prismatic">
    <origin rpy="3.1416 0 0" xyz="0 0.8 0"/>
    <parent link="link_5"/>
    <child link="link_7"/>
    <axis xyz="0 0 0"/>
    <limit effort="100" lower="-0.03" upper="0" velocity="3"/>
  </joint>
</robot>
